{
 "cells": [
  {
   "cell_type": "code",
   "execution_count": 1,
   "id": "37b33851",
   "metadata": {},
   "outputs": [
    {
     "name": "stderr",
     "output_type": "stream",
     "text": [
      "2023-02-09 18:05:08.933705: W tensorflow/stream_executor/platform/default/dso_loader.cc:64] Could not load dynamic library 'libcudart.so.11.0'; dlerror: libcudart.so.11.0: cannot open shared object file: No such file or directory\n",
      "2023-02-09 18:05:08.933772: I tensorflow/stream_executor/cuda/cudart_stub.cc:29] Ignore above cudart dlerror if you do not have a GPU set up on your machine.\n"
     ]
    }
   ],
   "source": [
    "import matplotlib.pyplot as plt\n",
    "import numpy as np\n",
    "import pandas as pd\n",
    "import tensorflow as tf\n",
    "\n",
    "from sklearn.metrics import accuracy_score, precision_score, recall_score\n",
    "from sklearn.model_selection import train_test_split\n",
    "from tensorflow.keras import layers, losses\n",
    "from tensorflow.keras.datasets import fashion_mnist\n",
    "from tensorflow.keras.models import Model\n"
   ]
  },
  {
   "cell_type": "code",
   "execution_count": 12,
   "id": "2b6f1201",
   "metadata": {},
   "outputs": [
    {
     "name": "stdout",
     "output_type": "stream",
     "text": [
      "Found 1600 files belonging to 2 classes.\n",
      "Using 1280 files for training.\n"
     ]
    }
   ],
   "source": [
    "x_train = tf.keras.utils.image_dataset_from_directory(\n",
    "  \"/home/mike/Downloads/cats vs rabbits/train-cat-rabbit\",\n",
    "  validation_split=0.2,\n",
    "  subset=\"training\",\n",
    "  seed=123,\n",
    "  image_size=(180, 180),\n",
    "  batch_size=32)"
   ]
  },
  {
   "cell_type": "code",
   "execution_count": 13,
   "id": "a3252006",
   "metadata": {},
   "outputs": [
    {
     "name": "stdout",
     "output_type": "stream",
     "text": [
      "Found 15 files belonging to 2 classes.\n"
     ]
    }
   ],
   "source": [
    "x_test = tf.keras.utils.image_dataset_from_directory(\n",
    "  \"/home/mike/Downloads/cats vs rabbits/test-images\",\n",
    "  seed=123,\n",
    "  image_size=(180, 180),\n",
    "  batch_size=32)"
   ]
  },
  {
   "cell_type": "code",
   "execution_count": 14,
   "id": "43715d33",
   "metadata": {},
   "outputs": [
    {
     "name": "stdout",
     "output_type": "stream",
     "text": [
      "Found 414 files belonging to 2 classes.\n",
      "Using 82 files for validation.\n"
     ]
    }
   ],
   "source": [
    "x_val = tf.keras.utils.image_dataset_from_directory(\n",
    "  \"/home/mike/Downloads/cats vs rabbits/val-cat-rabbit\",\n",
    "  validation_split=0.2,\n",
    "  subset=\"validation\",\n",
    "  seed=123,\n",
    "  image_size=(180, 180),\n",
    "  batch_size=32)"
   ]
  },
  {
   "cell_type": "code",
   "execution_count": 19,
   "id": "fec10134",
   "metadata": {},
   "outputs": [],
   "source": [
    "# x_train = x_train.astype('float32') / 255.\n",
    "# x_test = x_test.astype('float32') / 255."
   ]
  },
  {
   "cell_type": "code",
   "execution_count": 15,
   "id": "b20806b6",
   "metadata": {},
   "outputs": [],
   "source": [
    "latent_dim = 64 \n",
    "\n",
    "class Autoencoder(Model):\n",
    "  def __init__(self, latent_dim):\n",
    "    super(Autoencoder, self).__init__()\n",
    "    self.latent_dim = latent_dim   \n",
    "    self.encoder = tf.keras.Sequential([\n",
    "      layers.Flatten(),\n",
    "      layers.Dense(latent_dim, activation='relu'),\n",
    "    ])\n",
    "    self.decoder = tf.keras.Sequential([\n",
    "      layers.Dense(784, activation='sigmoid'),\n",
    "      layers.Reshape((28, 28))\n",
    "    ])\n",
    "\n",
    "  def call(self, x):\n",
    "    encoded = self.encoder(x)\n",
    "    decoded = self.decoder(encoded)\n",
    "    return decoded\n",
    "\n",
    "autoencoder = Autoencoder(latent_dim)\n"
   ]
  },
  {
   "cell_type": "code",
   "execution_count": 16,
   "id": "7d128656",
   "metadata": {},
   "outputs": [],
   "source": [
    "autoencoder.compile(optimizer='adam', loss=losses.MeanSquaredError())\n"
   ]
  },
  {
   "cell_type": "code",
   "execution_count": 20,
   "id": "1f789717",
   "metadata": {},
   "outputs": [
    {
     "name": "stdout",
     "output_type": "stream",
     "text": [
      "Epoch 1/10\n"
     ]
    },
    {
     "ename": "InvalidArgumentError",
     "evalue": "Graph execution error:\n\nDetected at node 'mean_squared_error/SquaredDifference' defined at (most recent call last):\n    File \"/home/mike/anaconda3/envs/tensorflow/lib/python3.10/runpy.py\", line 196, in _run_module_as_main\n      return _run_code(code, main_globals, None,\n    File \"/home/mike/anaconda3/envs/tensorflow/lib/python3.10/runpy.py\", line 86, in _run_code\n      exec(code, run_globals)\n    File \"/home/mike/anaconda3/envs/tensorflow/lib/python3.10/site-packages/ipykernel_launcher.py\", line 16, in <module>\n      app.launch_new_instance()\n    File \"/home/mike/anaconda3/envs/tensorflow/lib/python3.10/site-packages/traitlets/config/application.py\", line 846, in launch_instance\n      app.start()\n    File \"/home/mike/anaconda3/envs/tensorflow/lib/python3.10/site-packages/ipykernel/kernelapp.py\", line 677, in start\n      self.io_loop.start()\n    File \"/home/mike/anaconda3/envs/tensorflow/lib/python3.10/site-packages/tornado/platform/asyncio.py\", line 199, in start\n      self.asyncio_loop.run_forever()\n    File \"/home/mike/anaconda3/envs/tensorflow/lib/python3.10/asyncio/base_events.py\", line 600, in run_forever\n      self._run_once()\n    File \"/home/mike/anaconda3/envs/tensorflow/lib/python3.10/asyncio/base_events.py\", line 1896, in _run_once\n      handle._run()\n    File \"/home/mike/anaconda3/envs/tensorflow/lib/python3.10/asyncio/events.py\", line 80, in _run\n      self._context.run(self._callback, *self._args)\n    File \"/home/mike/anaconda3/envs/tensorflow/lib/python3.10/site-packages/ipykernel/kernelbase.py\", line 471, in dispatch_queue\n      await self.process_one()\n    File \"/home/mike/anaconda3/envs/tensorflow/lib/python3.10/site-packages/ipykernel/kernelbase.py\", line 460, in process_one\n      await dispatch(*args)\n    File \"/home/mike/anaconda3/envs/tensorflow/lib/python3.10/site-packages/ipykernel/kernelbase.py\", line 367, in dispatch_shell\n      await result\n    File \"/home/mike/anaconda3/envs/tensorflow/lib/python3.10/site-packages/ipykernel/kernelbase.py\", line 662, in execute_request\n      reply_content = await reply_content\n    File \"/home/mike/anaconda3/envs/tensorflow/lib/python3.10/site-packages/ipykernel/ipkernel.py\", line 360, in do_execute\n      res = shell.run_cell(code, store_history=store_history, silent=silent)\n    File \"/home/mike/anaconda3/envs/tensorflow/lib/python3.10/site-packages/ipykernel/zmqshell.py\", line 532, in run_cell\n      return super().run_cell(*args, **kwargs)\n    File \"/home/mike/anaconda3/envs/tensorflow/lib/python3.10/site-packages/IPython/core/interactiveshell.py\", line 2880, in run_cell\n      result = self._run_cell(\n    File \"/home/mike/anaconda3/envs/tensorflow/lib/python3.10/site-packages/IPython/core/interactiveshell.py\", line 2935, in _run_cell\n      return runner(coro)\n    File \"/home/mike/anaconda3/envs/tensorflow/lib/python3.10/site-packages/IPython/core/async_helpers.py\", line 129, in _pseudo_sync_runner\n      coro.send(None)\n    File \"/home/mike/anaconda3/envs/tensorflow/lib/python3.10/site-packages/IPython/core/interactiveshell.py\", line 3134, in run_cell_async\n      has_raised = await self.run_ast_nodes(code_ast.body, cell_name,\n    File \"/home/mike/anaconda3/envs/tensorflow/lib/python3.10/site-packages/IPython/core/interactiveshell.py\", line 3337, in run_ast_nodes\n      if await self.run_code(code, result, async_=asy):\n    File \"/home/mike/anaconda3/envs/tensorflow/lib/python3.10/site-packages/IPython/core/interactiveshell.py\", line 3397, in run_code\n      exec(code_obj, self.user_global_ns, self.user_ns)\n    File \"/tmp/ipykernel_147215/3472265564.py\", line 1, in <cell line: 1>\n      autoencoder.fit(x_train,\n    File \"/home/mike/anaconda3/envs/tensorflow/lib/python3.10/site-packages/keras/utils/traceback_utils.py\", line 64, in error_handler\n      return fn(*args, **kwargs)\n    File \"/home/mike/anaconda3/envs/tensorflow/lib/python3.10/site-packages/keras/engine/training.py\", line 1409, in fit\n      tmp_logs = self.train_function(iterator)\n    File \"/home/mike/anaconda3/envs/tensorflow/lib/python3.10/site-packages/keras/engine/training.py\", line 1051, in train_function\n      return step_function(self, iterator)\n    File \"/home/mike/anaconda3/envs/tensorflow/lib/python3.10/site-packages/keras/engine/training.py\", line 1040, in step_function\n      outputs = model.distribute_strategy.run(run_step, args=(data,))\n    File \"/home/mike/anaconda3/envs/tensorflow/lib/python3.10/site-packages/keras/engine/training.py\", line 1030, in run_step\n      outputs = model.train_step(data)\n    File \"/home/mike/anaconda3/envs/tensorflow/lib/python3.10/site-packages/keras/engine/training.py\", line 890, in train_step\n      loss = self.compute_loss(x, y, y_pred, sample_weight)\n    File \"/home/mike/anaconda3/envs/tensorflow/lib/python3.10/site-packages/keras/engine/training.py\", line 948, in compute_loss\n      return self.compiled_loss(\n    File \"/home/mike/anaconda3/envs/tensorflow/lib/python3.10/site-packages/keras/engine/compile_utils.py\", line 201, in __call__\n      loss_value = loss_obj(y_t, y_p, sample_weight=sw)\n    File \"/home/mike/anaconda3/envs/tensorflow/lib/python3.10/site-packages/keras/losses.py\", line 139, in __call__\n      losses = call_fn(y_true, y_pred)\n    File \"/home/mike/anaconda3/envs/tensorflow/lib/python3.10/site-packages/keras/losses.py\", line 243, in call\n      return ag_fn(y_true, y_pred, **self._fn_kwargs)\n    File \"/home/mike/anaconda3/envs/tensorflow/lib/python3.10/site-packages/keras/losses.py\", line 1327, in mean_squared_error\n      return backend.mean(tf.math.squared_difference(y_pred, y_true), axis=-1)\nNode: 'mean_squared_error/SquaredDifference'\nIncompatible shapes: [32,28,28] vs. [32]\n\t [[{{node mean_squared_error/SquaredDifference}}]] [Op:__inference_train_function_1343]",
     "output_type": "error",
     "traceback": [
      "\u001b[0;31m---------------------------------------------------------------------------\u001b[0m",
      "\u001b[0;31mInvalidArgumentError\u001b[0m                      Traceback (most recent call last)",
      "Input \u001b[0;32mIn [20]\u001b[0m, in \u001b[0;36m<cell line: 1>\u001b[0;34m()\u001b[0m\n\u001b[0;32m----> 1\u001b[0m \u001b[43mautoencoder\u001b[49m\u001b[38;5;241;43m.\u001b[39;49m\u001b[43mfit\u001b[49m\u001b[43m(\u001b[49m\u001b[43mx_train\u001b[49m\u001b[43m,\u001b[49m\n\u001b[1;32m      2\u001b[0m \u001b[43m                \u001b[49m\u001b[43mepochs\u001b[49m\u001b[38;5;241;43m=\u001b[39;49m\u001b[38;5;241;43m10\u001b[39;49m\u001b[43m,\u001b[49m\n\u001b[1;32m      3\u001b[0m \u001b[43m                \u001b[49m\u001b[43mshuffle\u001b[49m\u001b[38;5;241;43m=\u001b[39;49m\u001b[38;5;28;43;01mTrue\u001b[39;49;00m\u001b[43m,\u001b[49m\n\u001b[1;32m      4\u001b[0m \u001b[43m                \u001b[49m\u001b[43mvalidation_data\u001b[49m\u001b[38;5;241;43m=\u001b[39;49m\u001b[43m(\u001b[49m\u001b[43mx_test\u001b[49m\u001b[43m,\u001b[49m\u001b[43m \u001b[49m\u001b[43mx_test\u001b[49m\u001b[43m)\u001b[49m\u001b[43m)\u001b[49m\n",
      "File \u001b[0;32m~/anaconda3/envs/tensorflow/lib/python3.10/site-packages/keras/utils/traceback_utils.py:67\u001b[0m, in \u001b[0;36mfilter_traceback.<locals>.error_handler\u001b[0;34m(*args, **kwargs)\u001b[0m\n\u001b[1;32m     65\u001b[0m \u001b[38;5;28;01mexcept\u001b[39;00m \u001b[38;5;167;01mException\u001b[39;00m \u001b[38;5;28;01mas\u001b[39;00m e:  \u001b[38;5;66;03m# pylint: disable=broad-except\u001b[39;00m\n\u001b[1;32m     66\u001b[0m   filtered_tb \u001b[38;5;241m=\u001b[39m _process_traceback_frames(e\u001b[38;5;241m.\u001b[39m__traceback__)\n\u001b[0;32m---> 67\u001b[0m   \u001b[38;5;28;01mraise\u001b[39;00m e\u001b[38;5;241m.\u001b[39mwith_traceback(filtered_tb) \u001b[38;5;28;01mfrom\u001b[39;00m \u001b[38;5;28mNone\u001b[39m\n\u001b[1;32m     68\u001b[0m \u001b[38;5;28;01mfinally\u001b[39;00m:\n\u001b[1;32m     69\u001b[0m   \u001b[38;5;28;01mdel\u001b[39;00m filtered_tb\n",
      "File \u001b[0;32m~/anaconda3/envs/tensorflow/lib/python3.10/site-packages/tensorflow/python/eager/execute.py:54\u001b[0m, in \u001b[0;36mquick_execute\u001b[0;34m(op_name, num_outputs, inputs, attrs, ctx, name)\u001b[0m\n\u001b[1;32m     52\u001b[0m \u001b[38;5;28;01mtry\u001b[39;00m:\n\u001b[1;32m     53\u001b[0m   ctx\u001b[38;5;241m.\u001b[39mensure_initialized()\n\u001b[0;32m---> 54\u001b[0m   tensors \u001b[38;5;241m=\u001b[39m pywrap_tfe\u001b[38;5;241m.\u001b[39mTFE_Py_Execute(ctx\u001b[38;5;241m.\u001b[39m_handle, device_name, op_name,\n\u001b[1;32m     55\u001b[0m                                       inputs, attrs, num_outputs)\n\u001b[1;32m     56\u001b[0m \u001b[38;5;28;01mexcept\u001b[39;00m core\u001b[38;5;241m.\u001b[39m_NotOkStatusException \u001b[38;5;28;01mas\u001b[39;00m e:\n\u001b[1;32m     57\u001b[0m   \u001b[38;5;28;01mif\u001b[39;00m name \u001b[38;5;129;01mis\u001b[39;00m \u001b[38;5;129;01mnot\u001b[39;00m \u001b[38;5;28;01mNone\u001b[39;00m:\n",
      "\u001b[0;31mInvalidArgumentError\u001b[0m: Graph execution error:\n\nDetected at node 'mean_squared_error/SquaredDifference' defined at (most recent call last):\n    File \"/home/mike/anaconda3/envs/tensorflow/lib/python3.10/runpy.py\", line 196, in _run_module_as_main\n      return _run_code(code, main_globals, None,\n    File \"/home/mike/anaconda3/envs/tensorflow/lib/python3.10/runpy.py\", line 86, in _run_code\n      exec(code, run_globals)\n    File \"/home/mike/anaconda3/envs/tensorflow/lib/python3.10/site-packages/ipykernel_launcher.py\", line 16, in <module>\n      app.launch_new_instance()\n    File \"/home/mike/anaconda3/envs/tensorflow/lib/python3.10/site-packages/traitlets/config/application.py\", line 846, in launch_instance\n      app.start()\n    File \"/home/mike/anaconda3/envs/tensorflow/lib/python3.10/site-packages/ipykernel/kernelapp.py\", line 677, in start\n      self.io_loop.start()\n    File \"/home/mike/anaconda3/envs/tensorflow/lib/python3.10/site-packages/tornado/platform/asyncio.py\", line 199, in start\n      self.asyncio_loop.run_forever()\n    File \"/home/mike/anaconda3/envs/tensorflow/lib/python3.10/asyncio/base_events.py\", line 600, in run_forever\n      self._run_once()\n    File \"/home/mike/anaconda3/envs/tensorflow/lib/python3.10/asyncio/base_events.py\", line 1896, in _run_once\n      handle._run()\n    File \"/home/mike/anaconda3/envs/tensorflow/lib/python3.10/asyncio/events.py\", line 80, in _run\n      self._context.run(self._callback, *self._args)\n    File \"/home/mike/anaconda3/envs/tensorflow/lib/python3.10/site-packages/ipykernel/kernelbase.py\", line 471, in dispatch_queue\n      await self.process_one()\n    File \"/home/mike/anaconda3/envs/tensorflow/lib/python3.10/site-packages/ipykernel/kernelbase.py\", line 460, in process_one\n      await dispatch(*args)\n    File \"/home/mike/anaconda3/envs/tensorflow/lib/python3.10/site-packages/ipykernel/kernelbase.py\", line 367, in dispatch_shell\n      await result\n    File \"/home/mike/anaconda3/envs/tensorflow/lib/python3.10/site-packages/ipykernel/kernelbase.py\", line 662, in execute_request\n      reply_content = await reply_content\n    File \"/home/mike/anaconda3/envs/tensorflow/lib/python3.10/site-packages/ipykernel/ipkernel.py\", line 360, in do_execute\n      res = shell.run_cell(code, store_history=store_history, silent=silent)\n    File \"/home/mike/anaconda3/envs/tensorflow/lib/python3.10/site-packages/ipykernel/zmqshell.py\", line 532, in run_cell\n      return super().run_cell(*args, **kwargs)\n    File \"/home/mike/anaconda3/envs/tensorflow/lib/python3.10/site-packages/IPython/core/interactiveshell.py\", line 2880, in run_cell\n      result = self._run_cell(\n    File \"/home/mike/anaconda3/envs/tensorflow/lib/python3.10/site-packages/IPython/core/interactiveshell.py\", line 2935, in _run_cell\n      return runner(coro)\n    File \"/home/mike/anaconda3/envs/tensorflow/lib/python3.10/site-packages/IPython/core/async_helpers.py\", line 129, in _pseudo_sync_runner\n      coro.send(None)\n    File \"/home/mike/anaconda3/envs/tensorflow/lib/python3.10/site-packages/IPython/core/interactiveshell.py\", line 3134, in run_cell_async\n      has_raised = await self.run_ast_nodes(code_ast.body, cell_name,\n    File \"/home/mike/anaconda3/envs/tensorflow/lib/python3.10/site-packages/IPython/core/interactiveshell.py\", line 3337, in run_ast_nodes\n      if await self.run_code(code, result, async_=asy):\n    File \"/home/mike/anaconda3/envs/tensorflow/lib/python3.10/site-packages/IPython/core/interactiveshell.py\", line 3397, in run_code\n      exec(code_obj, self.user_global_ns, self.user_ns)\n    File \"/tmp/ipykernel_147215/3472265564.py\", line 1, in <cell line: 1>\n      autoencoder.fit(x_train,\n    File \"/home/mike/anaconda3/envs/tensorflow/lib/python3.10/site-packages/keras/utils/traceback_utils.py\", line 64, in error_handler\n      return fn(*args, **kwargs)\n    File \"/home/mike/anaconda3/envs/tensorflow/lib/python3.10/site-packages/keras/engine/training.py\", line 1409, in fit\n      tmp_logs = self.train_function(iterator)\n    File \"/home/mike/anaconda3/envs/tensorflow/lib/python3.10/site-packages/keras/engine/training.py\", line 1051, in train_function\n      return step_function(self, iterator)\n    File \"/home/mike/anaconda3/envs/tensorflow/lib/python3.10/site-packages/keras/engine/training.py\", line 1040, in step_function\n      outputs = model.distribute_strategy.run(run_step, args=(data,))\n    File \"/home/mike/anaconda3/envs/tensorflow/lib/python3.10/site-packages/keras/engine/training.py\", line 1030, in run_step\n      outputs = model.train_step(data)\n    File \"/home/mike/anaconda3/envs/tensorflow/lib/python3.10/site-packages/keras/engine/training.py\", line 890, in train_step\n      loss = self.compute_loss(x, y, y_pred, sample_weight)\n    File \"/home/mike/anaconda3/envs/tensorflow/lib/python3.10/site-packages/keras/engine/training.py\", line 948, in compute_loss\n      return self.compiled_loss(\n    File \"/home/mike/anaconda3/envs/tensorflow/lib/python3.10/site-packages/keras/engine/compile_utils.py\", line 201, in __call__\n      loss_value = loss_obj(y_t, y_p, sample_weight=sw)\n    File \"/home/mike/anaconda3/envs/tensorflow/lib/python3.10/site-packages/keras/losses.py\", line 139, in __call__\n      losses = call_fn(y_true, y_pred)\n    File \"/home/mike/anaconda3/envs/tensorflow/lib/python3.10/site-packages/keras/losses.py\", line 243, in call\n      return ag_fn(y_true, y_pred, **self._fn_kwargs)\n    File \"/home/mike/anaconda3/envs/tensorflow/lib/python3.10/site-packages/keras/losses.py\", line 1327, in mean_squared_error\n      return backend.mean(tf.math.squared_difference(y_pred, y_true), axis=-1)\nNode: 'mean_squared_error/SquaredDifference'\nIncompatible shapes: [32,28,28] vs. [32]\n\t [[{{node mean_squared_error/SquaredDifference}}]] [Op:__inference_train_function_1343]"
     ]
    }
   ],
   "source": [
    "autoencoder.fit(x_train, x_train,\n",
    "                epochs=10,\n",
    "                shuffle=True,\n",
    "                validation_data=(x_test, x_test))\n"
   ]
  },
  {
   "cell_type": "code",
   "execution_count": null,
   "id": "79cfca7e",
   "metadata": {},
   "outputs": [],
   "source": []
  }
 ],
 "metadata": {
  "kernelspec": {
   "display_name": "Python 3 (ipykernel)",
   "language": "python",
   "name": "python3"
  },
  "language_info": {
   "codemirror_mode": {
    "name": "ipython",
    "version": 3
   },
   "file_extension": ".py",
   "mimetype": "text/x-python",
   "name": "python",
   "nbconvert_exporter": "python",
   "pygments_lexer": "ipython3",
   "version": "3.10.4"
  }
 },
 "nbformat": 4,
 "nbformat_minor": 5
}
